<mujoco model="C:/Users/SG/OneDrive - IIT Kanpur/Documents/MATLAB Drive/Robots/New folder/Puma560.urdf">
  <compiler angle="radian"/>
  <worldbody>
      <geom size="0.15 0.01" pos="0 0 0.01" type="cylinder"/>
      <geom size="0.082 0.33" pos="0 0 0.33" type="cylinder" />
    <body name="solid" pos="0 0 0.669" quat="0.315322 0 0 0.948985">
      <joint name="joint1" pos="0 0 0" axis="0 0 1" range="-2.792 2.792"/>
      <geom size="0.082 0.13" pos="-0.035 0 0" quat="-0.707106 -2.44949e-07 0.707108 -2.44949e-07" type="cylinder"  rgba="1 0 0 1"/>
      <body name="solid_0" pos="-0.1622 0 0" quat="0.275623 -0.961266 0 0">
        <joint name="joint2" pos="0 0 0" axis="-1 0 0" range="-3.9269 0.7854"/>
        <geom size="0.0525 0.125 0.145" pos="-0.082 -0.056 -0.007" type="box" rgba="0 0.7 0.2 1"/>
        <geom size="0.0525 0.215 0.07" pos="-0.082 0.27 0.031" quat="0.996802 -0.0799147 0 0" type="box"  rgba="0 0.7 0.2 1"/>
        <geom size="0.0525 0.215 0.07" pos="-0.082 0.267 -0.039" quat="0.995004 0.0998334 0 0" type="box"  rgba="0 0.7 0.2 1"/>
        <body name="solid_1" pos="0.086 0.42 0" quat="0.453601 -0.891205 0 0">
          <joint name="joint3" pos="0 0 0" axis="-1 0 0" range="-0.7854 3.9269"/>
          <geom size="0.044 0.04 0.22" pos="-0.074 -0.034 0.13" quat="0.999688 -0.0249974 0 0" type="box" rgba="1 0 1 1"/>
          <geom size="0.044 0.04 0.22" pos="-0.074 0.015 0.13" quat="0.997551 0.0699428 0 0" type="box" rgba="1 0 1 1"/>
          <body name="solid_2" pos="-0.074 -0.02 0.353" quat="0.761362 0 0 0.648327">
            <joint name="joint4" pos="0 0 0" axis="0 0 1" range="-1.9198 2.967"/>
            <geom size="0.0435 0.0425 0.0195" pos="0 0 0.019" type="box" rgba="0 1 1 1"/>
            <body name="solid_3" pos="0 0 0.079" quat="0.99997 -0.00777642 0 0">
              <joint name="joint5" pos="0 0 0" axis="-1 0 0" range="-1.7453 1.7453"/>
              <geom size="0.041 0.044" quat="-0.707035 -2.44949e-07 0.707179 -2.44949e-07" type="cylinder"  rgba="0.65 0.16 0.16 1"/>
              <body name="solid_4" pos="0 0 -0.08" quat="1 0 0 2.5e-06">
                <joint name="joint6" pos="0 0 0" axis="0 0 1" range="-4.6425 4.6425"/>
                <geom size="0.019 0.025" pos="0 0 0.136" type="cylinder" rgba="0 0 0 1"/>
                <geom size="0.026 0.0235" pos="0 0 0.1845" type="cylinder" rgba="0 0 0 1"/>
                <geom size="0.015 0.015" pos="0 0 0.222" type="cylinder" rgba="0 0 0 1"/>
                  <site name="attachment_site" size="0.01" pos="0 0.0 0.25" quat="-1 1 1 1" rgba="1 0 0 1" group="1"/>
                <body name="GripperL" pos="0 0.007 0.23" quat="0.707105 0 0 0.707108">
                  <joint name="gripper::left" pos="0 0 0" axis="1 -4e-06 0" type="slide" range="-0.004 0.01"/>
                  <geom size="0.003 0.0105 0.0155" pos="2e-05 0 0.023" type="box"  rgba="0 0 1 1"/>
                </body>
                <body name="GripperR" pos="2e-05 -0.007 0.23" quat="0.707105 0 0 -0.707108">
                  <joint name="gripper::right" pos="0 0 0" axis="1 4e-06 0" type="slide" range="-0.004 0.01"/>
                  <geom size="0.003 0.0105 0.0155" pos="1.9e-05 0 0.023" type="box" rgba="1 1 0 1"/>
                </body>
              </body>
            </body>
          </body>
        </body>
      </body>
    </body>

    <body name="target" pos="0.5 0 .5" quat="0 1 0 0" mocap="true">
      <geom type="box" size=".025 .025 .025" contype="0" conaffinity="0" rgba=".6 .3 .3 .5"/>
      <site type="sphere" size="0.01" rgba="0 0 1 1" group="1"/>
    </body>

  </worldbody>
    <actuator>

        <motor name="joint1" joint="joint1"/>
        <motor name="joint2" joint="joint2"/>
        <motor name="joint3" joint="joint3"/>
        <motor name="joint4" joint="joint4"/>
        <motor name="joint5" joint="joint5"/>
        <motor name="joint6" joint="joint6"/>
        <motor name="gripper::left" joint="gripper::left"/>
        <motor name="gripper::right" joint="gripper::right"/>

    </actuator>

</mujoco>
