<?xml version="1.0"?>
<robot name="C:/Users/SG/OneDrive - IIT Kanpur/Documents/MATLAB Drive/Robots/New folder/Puma560.urdf" xmlns:xacro="http://ros.org/wiki/xacro">
  <link name="base_link">
  </link>
  <joint name="joint1" type="revolute">
    <parent link="base_link"/>
    <child link="solid"/>
    <axis xyz="0 0 1"/>
    <limit effort="97.6" lower="-2.792" upper="2.792" velocity="99999"/>
    <origin xyz="0 0 0.669" rpy="0 0 2.5"/>
  </joint>
  <link name="solid">
    <visual>
      <origin xyz="-0.035 0 0" rpy="3.141593 -1.570793 3.141593"/>
      <geometry>
        <cylinder radius="0.082" length="0.26"/>
      </geometry>
    </visual>
    <collision>
      <origin xyz="-0.035 0 0" rpy="3.141593 -1.570793 3.141593"/>
      <geometry>
        <cylinder radius="0.082" length="0.26"/>
      </geometry>
    </collision>
  </link>
  <joint name="joint2" type="revolute">
    <parent link="solid"/>
    <child link="solid_0"/>
    <axis xyz="-1 0 0"/>
    <limit effort="186.4" lower="-3.9269" upper="0.7854" velocity="99999"/>
    <origin xyz="-0.1622 0 0" rpy="-2.583117 0 0"/>
  </joint>
  <link name="solid_0">
    <visual>
      <origin xyz="-0.082 -0.056 -0.007" rpy="0 0 0"/>
      <geometry>
        <box size="0.105 0.25 0.29"/>
      </geometry>
    </visual>
    <collision>
      <origin xyz="-0.082 -0.056 -0.007" rpy="0 0 0"/>
      <geometry>
        <box size="0.105 0.25 0.29"/>
      </geometry>
    </collision>
    <visual>
      <origin xyz="-0.082 0.27 0.031" rpy="-0.16 0 0"/>
      <geometry>
        <box size="0.105 0.43 0.14"/>
      </geometry>
    </visual>
    <collision>
      <origin xyz="-0.082 0.27 0.031" rpy="-0.16 0 0"/>
      <geometry>
        <box size="0.105 0.43 0.14"/>
      </geometry>
    </collision>
    <visual>
      <origin xyz="-0.082 0.267 -0.039" rpy="0.2 0 0"/>
      <geometry>
        <box size="0.105 0.43 0.14"/>
      </geometry>
    </visual>
    <collision>
      <origin xyz="-0.082 0.267 -0.039" rpy="0.2 0 0"/>
      <geometry>
        <box size="0.105 0.43 0.14"/>
      </geometry>
    </collision>
  </link>
  <joint name="joint3" type="revolute">
    <parent link="solid_0"/>
    <child link="solid_1"/>
    <axis xyz="-1 0 0"/>
    <limit effort="89.4" lower="-0.7854" upper="3.9269" velocity="99999"/>
    <origin xyz="0.086 0.42 0" rpy="-2.19999 0 0"/>
  </joint>
  <link name="solid_1">
    <visual>
      <origin xyz="-0.074 -0.034 0.13" rpy="-0.05 0 0"/>
      <geometry>
        <box size="0.088 0.08 0.44"/>
      </geometry>
    </visual>
    <collision>
      <origin xyz="-0.074 -0.034 0.13" rpy="-0.05 0 0"/>
      <geometry>
        <box size="0.088 0.08 0.44"/>
      </geometry>
    </collision>
    <visual>
      <origin xyz="-0.074 0.015 0.13" rpy="0.14 0 0"/>
      <geometry>
        <box size="0.088 0.08 0.44"/>
      </geometry>
    </visual>
    <collision>
      <origin xyz="-0.074 0.015 0.13" rpy="0.14 0 0"/>
      <geometry>
        <box size="0.088 0.08 0.44"/>
      </geometry>
    </collision>
  </link>
  <joint name="joint4" type="revolute">
    <parent link="solid_1"/>
    <child link="solid_2"/>
    <axis xyz="0 0 1"/>
    <limit effort="24.2" lower="-1.9198" upper="2.967" velocity="99999"/>
    <origin xyz="-0.074 -0.02 0.353" rpy="0 0 1.410769"/>
  </joint>
  <link name="solid_2">
    <visual>
      <origin xyz="0 0 0.019" rpy="0 0 0"/>
      <geometry>
        <box size="0.087 0.085 0.039"/>
      </geometry>
    </visual>
    <collision>
      <origin xyz="0 0 0.019" rpy="0 0 0"/>
      <geometry>
        <box size="0.087 0.085 0.039"/>
      </geometry>
    </collision>
  </link>
  <joint name="joint5" type="revolute">
    <parent link="solid_2"/>
    <child link="solid_3"/>
    <axis xyz="-1 0 0"/>
    <limit effort="20.1" lower="-1.7453" upper="1.7453" velocity="99999"/>
    <origin xyz="0 0 0.079" rpy="-0.015553 0 0"/>
  </joint>
  <link name="solid_3">
    <visual>
      <origin xyz="0 0 0" rpy="3.141593 -1.570593 3.141593"/>
      <geometry>
        <cylinder radius="0.041" length="0.088"/>
      </geometry>
    </visual>
    <collision>
      <origin xyz="0 0 0" rpy="3.141593 -1.570593 3.141593"/>
      <geometry>
        <cylinder radius="0.041" length="0.088"/>
      </geometry>
    </collision>
  </link>
  <joint name="joint6" type="revolute">
    <parent link="solid_3"/>
    <child link="solid_4"/>
    <axis xyz="0 0 1"/>
    <limit effort="21.3" lower="-4.6425" upper="4.6425" velocity="99999"/>
    <origin xyz="0 0 -0.08" rpy="0 0 0.000005"/>
  </joint>
  <link name="solid_4">
    <visual>
      <origin xyz="0 0 0.136" rpy="0 0 0"/>
      <geometry>
        <cylinder radius="0.019" length="0.05"/>
      </geometry>
    </visual>
    <collision>
      <origin xyz="0 0 0.136" rpy="0 0 0"/>
      <geometry>
        <cylinder radius="0.019" length="0.05"/>
      </geometry>
    </collision>
    <visual>
      <origin xyz="0 0 0.1845" rpy="0 0 0"/>
      <geometry>
        <cylinder radius="0.026" length="0.047"/>
      </geometry>
    </visual>
    <collision>
      <origin xyz="0 0 0.1845" rpy="0 0 0"/>
      <geometry>
        <cylinder radius="0.026" length="0.047"/>
      </geometry>
    </collision>
    <visual>
      <origin xyz="0 0 0.222" rpy="0 0 0"/>
      <geometry>
        <cylinder radius="0.015" length="0.03"/>
      </geometry>
    </visual>
    <collision>
      <origin xyz="0 0 0.222" rpy="0 0 0"/>
      <geometry>
        <cylinder radius="0.015" length="0.03"/>
      </geometry>
    </collision>
  </link>
  <joint name="gripper::left" type="prismatic">
    <parent link="solid_4"/>
    <child link="GripperL"/>
    <axis xyz="1 -0.000004 0"/>
    <origin xyz="0 0.007 0.23" rpy="0 0 1.5708"/>
    <limit effort="10" lower="-0.004" upper="0.01" velocity="10"/>
  </joint>
  <link name="GripperL">
    <visual>
      <origin xyz="0.00002 0 0.023" rpy="0 0 0"/>
      <geometry>
        <box size="0.006 0.021 0.031"/>
      </geometry>
    </visual>
    <collision>
      <origin xyz="0.00002 0 0.023" rpy="0 0 0"/>
      <geometry>
        <box size="0.006 0.021 0.031"/>
      </geometry>
    </collision>
  </link>
  <joint name="gripper::right" type="prismatic">
    <parent link="solid_4"/>
    <child link="GripperR"/>
    <axis xyz="1 0.000004 0"/>
    <origin xyz="0.00002 -0.007 0.23" rpy="0 0 -1.5708"/>
    <limit effort="10" lower="-0.004" upper="0.01" velocity="10"/>
  </joint>
  <link name="GripperR">
    <visual>
      <origin xyz="0.000019 0 0.023" rpy="0 0 0"/>
      <geometry>
        <box size="0.006 0.021 0.031"/>
      </geometry>
    </visual>
    <collision>
      <origin xyz="0.000019 0 0.023" rpy="0 0 0"/>
      <geometry>
        <box size="0.006 0.021 0.031"/>
      </geometry>
    </collision>
  </link>
</robot>
